<?xml version="1.0" encoding="UTF-8"?>
<!-- Generated by org.testng.reporters.JUnitReportReporter -->
<testsuite hostname="LAPTOP-NEGDCA0S" failures="1" tests="5" name="practice_Test.InvoiceTest" time="27.768" errors="0" timestamp="2025-07-12T10:48:03 IST" skipped="3">
  <testcase classname="practice_Test.InvoiceTest" name="CreateInvoiceTest" time="5.216">
    <failure message="expected [Login] but found [Admin123@ Administrator1 - Home - vtiger CRM 5 - Commercial Open Source CRM]" type="java.lang.AssertionError">
      <![CDATA[java.lang.AssertionError: expected [Login] but found [Admin123@ Administrator1 - Home - vtiger CRM 5 - Commercial Open Source CRM]
at org.testng.Assert.fail(Assert.java:110)
at org.testng.Assert.failNotEquals(Assert.java:1577)
at org.testng.Assert.assertEqualsImpl(Assert.java:149)
at org.testng.Assert.assertEquals(Assert.java:131)
at org.testng.Assert.assertEquals(Assert.java:655)
at org.testng.Assert.assertEquals(Assert.java:665)
at practice_Test.InvoiceTest.CreateInvoiceTest(InvoiceTest.java:18)
at java.base/jdk.internal.reflect.DirectMethodHandleAccessor.invoke(DirectMethodHandleAccessor.java:103)
at java.base/java.lang.reflect.Method.invoke(Method.java:580)
at org.testng.internal.invokers.MethodInvocationHelper.invokeMethod(MethodInvocationHelper.java:139)
at org.testng.internal.invokers.TestInvoker.invokeMethod(TestInvoker.java:677)
at org.testng.internal.invokers.TestInvoker.retryFailed(TestInvoker.java:263)
at org.testng.internal.invokers.MethodRunner.runInSequence(MethodRunner.java:62)
at org.testng.internal.invokers.TestInvoker$MethodInvocationAgent.invoke(TestInvoker.java:969)
at org.testng.internal.invokers.TestInvoker.invokeTestMethods(TestInvoker.java:194)
at org.testng.internal.invokers.TestMethodWorker.invokeTestMethods(TestMethodWorker.java:148)
at org.testng.internal.invokers.TestMethodWorker.run(TestMethodWorker.java:128)
at java.base/java.util.ArrayList.forEach(ArrayList.java:1597)
at org.testng.TestRunner.privateRun(TestRunner.java:829)
at org.testng.TestRunner.run(TestRunner.java:602)
at org.testng.SuiteRunner.runTest(SuiteRunner.java:437)
at org.testng.SuiteRunner.runSequentially(SuiteRunner.java:431)
at org.testng.SuiteRunner.privateRun(SuiteRunner.java:391)
at org.testng.SuiteRunner.run(SuiteRunner.java:330)
at org.testng.SuiteRunnerWorker.runSuite(SuiteRunnerWorker.java:52)
at org.testng.SuiteRunnerWorker.run(SuiteRunnerWorker.java:95)
at org.testng.TestNG.runSuitesSequentially(TestNG.java:1256)
at org.testng.TestNG.runSuitesLocally(TestNG.java:1176)
at org.testng.TestNG.runSuites(TestNG.java:1099)
at org.testng.TestNG.run(TestNG.java:1067)
at org.testng.remote.AbstractRemoteTestNG.run(AbstractRemoteTestNG.java:115)
at org.testng.remote.RemoteTestNG.initAndRun(RemoteTestNG.java:293)
at org.testng.remote.RemoteTestNG.main(RemoteTestNG.java:91)
]]>
    </failure>
  </testcase> <!-- CreateInvoiceTest -->
  <system-out/>
  <testcase classname="practice_Test.InvoiceTest" name="CreateInvoiceTest" time="5.578">
    <skipped/>
  </testcase> <!-- CreateInvoiceTest -->
  <system-out/>
  <testcase classname="practice_Test.InvoiceTest" name="CreateInvoiceWithContactTest" time="5.818"/>
  <system-out/>
  <testcase classname="practice_Test.InvoiceTest" name="CreateInvoiceTest" time="5.753">
    <skipped/>
  </testcase> <!-- CreateInvoiceTest -->
  <system-out/>
  <testcase classname="practice_Test.InvoiceTest" name="CreateInvoiceTest" time="5.403">
    <skipped/>
  </testcase> <!-- CreateInvoiceTest -->
  <system-out/>
</testsuite> <!-- practice_Test.InvoiceTest -->
